<sdf version='1.7'>
  <world name='default'>
    <light name='sun' type='directional'>
      <cast_shadows>1</cast_shadows>
      <pose>0 0 10 0 -0 0</pose>
      <diffuse>0.8 0.8 0.8 1</diffuse>
      <specular>0.2 0.2 0.2 1</specular>
      <attenuation>
        <range>1000</range>
        <constant>0.9</constant>
        <linear>0.01</linear>
        <quadratic>0.001</quadratic>
      </attenuation>
      <direction>-0.5 0.1 -0.9</direction>
      <spot>
        <inner_angle>0</inner_angle>
        <outer_angle>0</outer_angle>
        <falloff>0</falloff>
      </spot>
    </light>
    <model name='ground_plane'>
      <static>1</static>
      <link name='link'>
        <collision name='collision'>
          <geometry>
            <plane>
              <normal>0 0 1</normal>
              <size>100 100</size>
            </plane>
          </geometry>
          <surface>
            <contact>
              <collide_bitmask>65535</collide_bitmask>
              <ode/>
            </contact>
            <friction>
              <ode>
                <mu>100</mu>
                <mu2>50</mu2>
              </ode>
              <torsional>
                <ode/>
              </torsional>
            </friction>
            <bounce/>
          </surface>
          <max_contacts>10</max_contacts>
        </collision>
        <visual name='visual'>
          <cast_shadows>0</cast_shadows>
          <geometry>
            <plane>
              <normal>0 0 1</normal>
              <size>100 100</size>
            </plane>
          </geometry>
          <material>
            <script>
              <uri>file://media/materials/scripts/gazebo.material</uri>
              <name>Gazebo/Grey</name>
            </script>
          </material>
        </visual>
        <self_collide>0</self_collide>
        <enable_wind>0</enable_wind>
        <kinematic>0</kinematic>
      </link>
    </model>
    <gravity>0 0 -9.8</gravity>
    <magnetic_field>6e-06 2.3e-05 -4.2e-05</magnetic_field>
    <atmosphere type='adiabatic'/>
    <physics type='ode'>
      <max_step_size>0.001</max_step_size>
      <real_time_factor>1</real_time_factor>
      <real_time_update_rate>1000</real_time_update_rate>
    </physics>
    <scene>
      <ambient>0.4 0.4 0.4 1</ambient>
      <background>0.7 0.7 0.7 1</background>
      <shadows>1</shadows>
    </scene>
    <wind/>
    <spherical_coordinates>
      <surface_model>EARTH_WGS84</surface_model>
      <latitude_deg>0</latitude_deg>
      <longitude_deg>0</longitude_deg>
      <elevation>0</elevation>
      <heading_deg>0</heading_deg>
    </spherical_coordinates>
    <model name='davinci_final'>
      <link name='Base'>
        <inertial>
          <pose>0.655776 0.37129 -0.348428 0 -0 0</pose>
          <mass>752.821</mass>
          <inertia>
            <ixx>73.8029</ixx>
            <ixy>5.77267</ixy>
            <ixz>0.0836249</ixz>
            <iyy>40.1585</iyy>
            <iyz>0.465633</iyz>
            <izz>89.8647</izz>
          </inertia>
        </inertial>
        <collision name='Base_collision'>
          <pose>0 0 0 0 -0 0</pose>
          <geometry>
            <mesh>
              <scale>1 1 1</scale>
              <uri>/home/johne/catkin_ws/src/davinci_final/meshes/Base.STL</uri>
            </mesh>
          </geometry>
          <max_contacts>10</max_contacts>
          <surface>
            <contact>
              <ode/>
            </contact>
            <bounce/>
            <friction>
              <torsional>
                <ode/>
              </torsional>
              <ode/>
            </friction>
          </surface>
        </collision>
        <visual name='Base_visual'>
          <pose>0 0 0 0 -0 0</pose>
          <geometry>
            <mesh>
              <scale>1 1 1</scale>
              <uri>/home/johne/catkin_ws/src/davinci_final/meshes/Base.STL</uri>
            </mesh>
          </geometry>
        </visual>
        <self_collide>0</self_collide>
        <enable_wind>0</enable_wind>
        <kinematic>0</kinematic>
      </link>
      <joint name='CamJ1' type='revolute'>
        <pose relative_to='Base'>1.1675 -0.2702 1.0583 1.8577 -0.12794 2.7468</pose>
        <parent>Base</parent>
        <child>CamL1</child>
        <axis>
          <xyz>0 1 0</xyz>
          <limit>
            <lower>-2.9671</lower>
            <upper>2.9671</upper>
            <effort>30</effort>
            <velocity>6.545</velocity>
          </limit>
          <dynamics>
            <spring_reference>0</spring_reference>
            <spring_stiffness>0</spring_stiffness>
          </dynamics>
        </axis>
      </joint>
      <link name='CamL1'>
        <pose relative_to='CamJ1'>0 0 0 0 -0 0</pose>
        <inertial>
          <pose>0.047469 -0.199385 -0.008342 0 -0 0</pose>
          <mass>20.0259</mass>
          <inertia>
            <ixx>0.282689</ixx>
            <ixy>0.00510627</ixy>
            <ixz>0.000298023</ixz>
            <iyy>0.121529</iyy>
            <iyz>0.00686648</iyz>
            <izz>0.359999</izz>
          </inertia>
        </inertial>
        <collision name='CamL1_collision'>
          <pose>0.047469 -0.199385 -0.008342 0 -0 0</pose>
          <geometry>
            <mesh>
              <scale>1 1 1</scale>
              <uri>/home/johne/catkin_ws/src/davinci_final/meshes/CamL1.STL</uri>
            </mesh>
          </geometry>
          <surface>
            <contact>
              <ode/>
            </contact>
            <friction>
              <ode/>
              <torsional>
                <ode/>
              </torsional>
            </friction>
            <bounce/>
          </surface>
          <max_contacts>10</max_contacts>
        </collision>
        <visual name='CamL1_visual'>
          <pose>0 0 0 0 -0 0</pose>
          <geometry>
            <mesh>
              <scale>1 1 1</scale>
              <uri>/home/johne/catkin_ws/src/davinci_final/meshes/CamL1.STL</uri>
            </mesh>
          </geometry>
        </visual>
        <gravity>0</gravity>
        <velocity_decay/>
        <self_collide>0</self_collide>
        <enable_wind>0</enable_wind>
        <kinematic>0</kinematic>
      </link>
      <joint name='CamJ2' type='revolute'>
        <pose relative_to='CamL1'>0 -0.15979 0 1.5708 -1.0689 -1.5708</pose>
        <parent>CamL1</parent>
        <child>CamL2</child>
        <axis>
          <xyz>0 0 1</xyz>
          <limit>
            <lower>-1.3232</lower>
            <upper>1.5</upper>
            <effort>20</effort>
            <velocity>5.4</velocity>
          </limit>
          <dynamics>
            <spring_reference>0</spring_reference>
            <spring_stiffness>0</spring_stiffness>
          </dynamics>
        </axis>
      </joint>
      <link name='CamL2'>
        <pose relative_to='CamJ2'>0 0 0 0 -0 0</pose>
        <inertial>
          <pose>-0.190133 -0.227541 -0.046564 0 -0 0</pose>
          <mass>24.6273</mass>
          <inertia>
            <ixx>1.03615</ixx>
            <ixy>0.158703</ixy>
            <ixz>1.58766e-07</ixz>
            <iyy>0.141637</iyy>
            <iyz>3.89666e-07</iyz>
            <izz>1.11527</izz>
          </inertia>
        </inertial>
        <collision name='CamL2_collision'>
          <pose>-0.190133 -0.227541 -0.046564 0 -0 0</pose>
          <geometry>
            <mesh>
              <scale>1 1 1</scale>
              <uri>/home/johne/catkin_ws/src/davinci_final/meshes/CamL2.STL</uri>
            </mesh>
          </geometry>
          <surface>
            <contact>
              <ode/>
            </contact>
            <friction>
              <ode/>
              <torsional>
                <ode/>
              </torsional>
            </friction>
            <bounce/>
          </surface>
          <max_contacts>10</max_contacts>
        </collision>
        <visual name='CamL2_visual'>
          <pose>0 0 0 0 -0 0</pose>
          <geometry>
            <mesh>
              <scale>1 1 1</scale>
              <uri>/home/johne/catkin_ws/src/davinci_final/meshes/CamL2.STL</uri>
            </mesh>
          </geometry>
        </visual>
        <gravity>0</gravity>
        <velocity_decay/>
        <self_collide>0</self_collide>
        <enable_wind>0</enable_wind>
        <kinematic>0</kinematic>
      </link>
      <joint name='CamJ3' type='revolute'>
        <pose relative_to='CamL2'>-0.2185 -0.59707 0 3.14159 -0 -2.5706</pose>
        <parent>CamL2</parent>
        <child>CamL3</child>
        <axis>
          <xyz>0 0 1</xyz>
          <limit>
            <lower>-1.4</lower>
            <upper>1.4</upper>
            <effort>30</effort>
            <velocity>6.3</velocity>
          </limit>
          <dynamics>
            <spring_reference>0</spring_reference>
            <spring_stiffness>0</spring_stiffness>
          </dynamics>
        </axis>
      </joint>
      <link name='CamL3'>
        <pose relative_to='CamJ3'>0 0 0 0 -0 0</pose>
        <inertial>
          <pose>0.071623 0.10881 0.046564 0 -0 0</pose>
          <mass>1.66804</mass>
          <inertia>
            <ixx>0.0338409</ixx>
            <ixy>0.00586958</ixy>
            <ixz>5.12441e-09</ixz>
            <iyy>0.00378034</iyy>
            <iyz>4.7545e-08</iyz>
            <izz>0.0372276</izz>
          </inertia>
        </inertial>
        <collision name='CamL3_collision'>
          <pose>0.071623 0.10881 0.046564 0 -0 0</pose>
          <geometry>
            <mesh>
              <scale>1 1 1</scale>
              <uri>/home/johne/catkin_ws/src/davinci_final/meshes/CamL3.STL</uri>
            </mesh>
          </geometry>
          <surface>
            <contact>
              <ode/>
            </contact>
            <friction>
              <ode/>
              <torsional>
                <ode/>
              </torsional>
            </friction>
            <bounce/>
          </surface>
          <max_contacts>10</max_contacts>
        </collision>
        <visual name='CamL3_visual'>
          <pose>0 0 0 0 -0 0</pose>
          <geometry>
            <mesh>
              <scale>1 1 1</scale>
              <uri>/home/johne/catkin_ws/src/davinci_final/meshes/CamL3.STL</uri>
            </mesh>
          </geometry>
        </visual>
        <gravity>0</gravity>
        <velocity_decay/>
        <self_collide>0</self_collide>
        <enable_wind>0</enable_wind>
        <kinematic>0</kinematic>
      </link>
      <joint name='CamJ4' type='prismatic'>
        <pose relative_to='CamL3'>0.13416 0 0.046564 0 0.49778 0</pose>
        <parent>CamL3</parent>
        <child>CamL4</child>
        <axis>
          <xyz>0 1 0</xyz>
          <limit>
            <lower>-1.337</lower>
            <upper>1.1623</upper>
            <effort>10</effort>
            <velocity>3.2</velocity>
          </limit>
          <dynamics>
            <spring_reference>0</spring_reference>
            <spring_stiffness>0</spring_stiffness>
          </dynamics>
        </axis>
      </joint>
      <link name='CamL4'>
        <pose relative_to='CamJ4'>0 0 0 0 -0 0</pose>
        <inertial>
          <pose>-3e-06 0.260787 0 0 -0 0</pose>
          <mass>0.186541</mass>
          <inertia>
            <ixx>0.01129</ixx>
            <ixy>-2.53853e-07</ixy>
            <ixz>-7.24924e-21</ixz>
            <iyy>0.000100003</iyy>
            <iyz>-9.89656e-19</iyz>
            <izz>0.01129</izz>
          </inertia>
        </inertial>
        <collision name='CamL4_collision'>
          <pose>-0 0.261225 0 0 -0 0</pose>
          <geometry>
            <mesh>
              <scale>1 1 1</scale>
              <uri>/home/johne/catkin_ws/src/davinci_final/meshes/CamL4.STL</uri>
            </mesh>
          </geometry>
          <surface>
            <contact>
              <ode/>
            </contact>
            <friction>
              <ode/>
              <torsional>
                <ode/>
              </torsional>
            </friction>
            <bounce/>
          </surface>
          <max_contacts>10</max_contacts>
        </collision>
        <collision name='CamL4_fixed_joint_lump__Lens_collision_1'>
          <pose>-0.003104 -0.162542 -0 0 0 -1.57</pose>
          <geometry>
            <mesh>
              <scale>1 1 1</scale>
              <uri>/home/johne/catkin_ws/src/davinci_final/meshes/Lens.STL</uri>
            </mesh>
          </geometry>
          <surface>
            <contact>
              <ode/>
            </contact>
            <friction>
              <ode/>
              <torsional>
                <ode/>
              </torsional>
            </friction>
            <bounce/>
          </surface>
          <max_contacts>10</max_contacts>
        </collision>
        <visual name='CamL4_visual'>
          <pose>0 0 0 0 -0 0</pose>
          <geometry>
            <mesh>
              <scale>1 1 1</scale>
              <uri>/home/johne/catkin_ws/src/davinci_final/meshes/CamL4.STL</uri>
            </mesh>
          </geometry>
        </visual>
        <velocity_decay/>
        <velocity_decay/>
        <sensor name='camera' type='depth'>
          <always_on>1</always_on>
          <visualize>1</visualize>
          <camera>
            <horizontal_fov>1.047</horizontal_fov>
            <image>
              <width>640</width>
              <height>480</height>
              <format>R8G8B8</format>
            </image>
            <depth_camera>
              <output>depths</output>
            </depth_camera>
            <clip>
              <near>0.1</near>
              <far>100</far>
            </clip>
          </camera>
          <plugin name='camera_controller' filename='libgazebo_ros_openni_kinect.so'>
            <baseline>0.2</baseline>
            <alwaysOn>1</alwaysOn>
            <updateRate>10.0</updateRate>
            <cameraName>your_camera</cameraName>
            <frameName>your_camera_link</frameName>
            <imageTopicName>rgb/image_raw</imageTopicName>
            <depthImageTopicName>depth/image_raw</depthImageTopicName>
            <pointCloudTopicName>depth/points</pointCloudTopicName>
            <cameraInfoTopicName>rgb/camera_info</cameraInfoTopicName>
            <depthImageCameraInfoTopicName>depth/camera_info</depthImageCameraInfoTopicName>
            <pointCloudCutoff>0.4</pointCloudCutoff>
            <hackBaseline>0.07</hackBaseline>
            <distortionK1>0.0</distortionK1>
            <distortionK2>0.0</distortionK2>
            <distortionK3>0.0</distortionK3>
            <distortionT1>0.0</distortionT1>
            <distortionT2>0.0</distortionT2>
            <CxPrime>0.0</CxPrime>
            <Cx>0.0</Cx>
            <Cy>0.0</Cy>
            <focalLength>0.0</focalLength>
            <robotNamespace>/</robotNamespace>
          </plugin>
          <pose>0 -0.16254 0 0 0 -1.57</pose>
        </sensor>
        <gravity>0</gravity>
        <velocity_decay/>
        <self_collide>0</self_collide>
        <enable_wind>0</enable_wind>
        <kinematic>0</kinematic>
      </link>
      <joint name='GripJ1' type='revolute'>
        <pose relative_to='Base'>0.63571 -0.50691 1.3515 2.0171 -0.11609 -2.9083</pose>
        <parent>Base</parent>
        <child>GripL1</child>
        <axis>
          <xyz>0 1 0</xyz>
          <limit>
            <lower>-2.9671</lower>
            <upper>2.9671</upper>
            <effort>30</effort>
            <velocity>6.545</velocity>
          </limit>
          <dynamics>
            <spring_reference>0</spring_reference>
            <spring_stiffness>0</spring_stiffness>
          </dynamics>
        </axis>
      </joint>
      <link name='GripL1'>
        <pose relative_to='GripJ1'>0 0 0 0 -0 0</pose>
        <inertial>
          <pose>0.04891 -0.194432 -0.008142 0 -0 0</pose>
          <mass>20.5182</mass>
          <inertia>
            <ixx>0.295731</ixx>
            <ixy>0.00173665</ixy>
            <ixz>5.73797e-05</ixz>
            <iyy>0.123815</iyy>
            <iyz>0.00769399</iyz>
            <izz>0.374506</izz>
          </inertia>
        </inertial>
        <collision name='GripL1_collision'>
          <pose>0.04891 -0.194432 -0.008142 0 -0 0</pose>
          <geometry>
            <mesh>
              <scale>1 1 1</scale>
              <uri>/home/johne/catkin_ws/src/davinci_final/meshes/GripL1.STL</uri>
            </mesh>
          </geometry>
          <surface>
            <contact>
              <ode/>
            </contact>
            <friction>
              <ode/>
              <torsional>
                <ode/>
              </torsional>
            </friction>
            <bounce/>
          </surface>
          <max_contacts>10</max_contacts>
        </collision>
        <visual name='GripL1_visual'>
          <pose>0 0 0 0 -0 0</pose>
          <geometry>
            <mesh>
              <scale>1 1 1</scale>
              <uri>/home/johne/catkin_ws/src/davinci_final/meshes/GripL1.STL</uri>
            </mesh>
          </geometry>
        </visual>
        <gravity>0</gravity>
        <velocity_decay/>
        <self_collide>0</self_collide>
        <enable_wind>0</enable_wind>
        <kinematic>0</kinematic>
      </link>
      <joint name='GripJ2' type='revolute'>
        <pose relative_to='GripL1'>0 -0.12945 0 -1.5708 -1.3625 1.5708</pose>
        <parent>GripL1</parent>
        <child>GripL2</child>
        <axis>
          <xyz>0 0 1</xyz>
          <limit>
            <lower>-3.7</lower>
            <upper>3.2</upper>
            <effort>20</effort>
            <velocity>5.3</velocity>
          </limit>
          <dynamics>
            <spring_reference>0</spring_reference>
            <spring_stiffness>0</spring_stiffness>
          </dynamics>
        </axis>
      </joint>
      <link name='GripL2'>
        <pose relative_to='GripJ2'>0 0 0 0 -0 0</pose>
        <inertial>
          <pose>-0.160901 -0.148755 -0.046564 0 -0 0</pose>
          <mass>17.6002</mass>
          <inertia>
            <ixx>0.406796</ixx>
            <ixy>0.0872148</ixy>
            <ixz>1.00833e-07</ixz>
            <iyy>0.0994939</iyy>
            <iyz>2.24146e-07</iyz>
            <izz>0.461656</izz>
          </inertia>
        </inertial>
        <collision name='GripL2_collision'>
          <pose>-0.160901 -0.148755 -0.046564 0 -0 0</pose>
          <geometry>
            <mesh>
              <scale>1 1 1</scale>
              <uri>/home/johne/catkin_ws/src/davinci_final/meshes/GripL2.STL</uri>
            </mesh>
          </geometry>
          <surface>
            <contact>
              <ode/>
            </contact>
            <friction>
              <ode/>
              <torsional>
                <ode/>
              </torsional>
            </friction>
            <bounce/>
          </surface>
          <max_contacts>10</max_contacts>
        </collision>
        <visual name='GripL2_visual'>
          <pose>0 0 0 0 -0 0</pose>
          <geometry>
            <mesh>
              <scale>1 1 1</scale>
              <uri>/home/johne/catkin_ws/src/davinci_final/meshes/GripL2.STL</uri>
            </mesh>
          </geometry>
        </visual>
        <gravity>0</gravity>
        <velocity_decay/>
        <self_collide>0</self_collide>
        <enable_wind>0</enable_wind>
        <kinematic>0</kinematic>
      </link>
      <joint name='GripJ3' type='revolute'>
        <pose relative_to='GripL2'>-0.1943 -0.42281 0 -3.14159 0 3.0389</pose>
        <parent>GripL2</parent>
        <child>GripL3</child>
        <axis>
          <xyz>0 0 1</xyz>
          <limit>
            <lower>-2.3</lower>
            <upper>2.3</upper>
            <effort>30</effort>
            <velocity>5.3</velocity>
          </limit>
          <dynamics>
            <spring_reference>0</spring_reference>
            <spring_stiffness>0</spring_stiffness>
          </dynamics>
        </axis>
      </joint>
      <link name='GripL3'>
        <pose relative_to='GripJ3'>0 0 0 0 -0 0</pose>
        <inertial>
          <pose>0.071623 0.10881 0.046564 0 -0 0</pose>
          <mass>1.66804</mass>
          <inertia>
            <ixx>0.033841</ixx>
            <ixy>0.0058696</ixy>
            <ixz>2.00591e-09</ixz>
            <iyy>0.00378035</iyy>
            <iyz>1.88494e-08</iyz>
            <izz>0.0372277</izz>
          </inertia>
        </inertial>
        <collision name='GripL3_collision'>
          <pose>0.071623 0.10881 0.046564 0 -0 0</pose>
          <geometry>
            <mesh>
              <scale>1 1 1</scale>
              <uri>/home/johne/catkin_ws/src/davinci_final/meshes/GripL3.STL</uri>
            </mesh>
          </geometry>
          <surface>
            <contact>
              <ode/>
            </contact>
            <friction>
              <ode/>
              <torsional>
                <ode/>
              </torsional>
            </friction>
            <bounce/>
          </surface>
          <max_contacts>10</max_contacts>
        </collision>
        <visual name='GripL3_visual'>
          <pose>0 0 0 0 -0 0</pose>
          <geometry>
            <mesh>
              <scale>1 1 1</scale>
              <uri>/home/johne/catkin_ws/src/davinci_final/meshes/GripL3.STL</uri>
            </mesh>
          </geometry>
        </visual>
        <gravity>0</gravity>
        <velocity_decay/>
        <self_collide>0</self_collide>
        <enable_wind>0</enable_wind>
        <kinematic>0</kinematic>
      </link>
      <joint name='GripJ4' type='prismatic'>
        <pose relative_to='GripL3'>0.13416 0 0.046564 3.14159 0.72256 3.14159</pose>
        <parent>GripL3</parent>
        <child>GripL4</child>
        <axis>
          <xyz>0 1 0</xyz>
          <limit>
            <lower>-1.182</lower>
            <upper>1.293</upper>
            <effort>20</effort>
            <velocity>3.4</velocity>
          </limit>
          <dynamics>
            <spring_reference>0</spring_reference>
            <spring_stiffness>0</spring_stiffness>
          </dynamics>
        </axis>
      </joint>
      <link name='GripL4'>
        <pose relative_to='GripJ4'>0 0 0 0 -0 0</pose>
        <inertial>
          <pose>-0.000104 0.082733 0.000274 0 -0 0</pose>
          <mass>0.20015</mass>
          <inertia>
            <ixx>0.0133701</ixx>
            <ixy>-8.44081e-06</ixy>
            <ixz>1.81887e-07</ixz>
            <iyy>4.67103e-06</iyy>
            <iyz>1.54369e-05</iyz>
            <izz>0.0133717</izz>
          </inertia>
        </inertial>
        <collision name='GripL4_collision'>
          <pose>-0 0.087493 0.000173 0 -0 0</pose>
          <geometry>
            <mesh>
              <scale>1 1 1</scale>
              <uri>/home/johne/catkin_ws/src/davinci_final/meshes/GripL4.STL</uri>
            </mesh>
          </geometry>
          <surface>
            <contact>
              <ode/>
            </contact>
            <friction>
              <ode/>
              <torsional>
                <ode/>
              </torsional>
            </friction>
            <bounce/>
          </surface>
          <max_contacts>10</max_contacts>
        </collision>
        <collision name='GripL4_fixed_joint_lump__Gripper2_collision_1'>
          <pose>-0.009111 -0.329267 0.009 0 -0 0.35499</pose>
          <geometry>
            <mesh>
              <scale>1 1 1</scale>
              <uri>/home/johne/catkin_ws/src/davinci_final/meshes/Gripper2.STL</uri>
            </mesh>
          </geometry>
          <surface>
            <contact>
              <ode/>
            </contact>
            <friction>
              <ode/>
              <torsional>
                <ode/>
              </torsional>
            </friction>
            <bounce/>
          </surface>
          <max_contacts>10</max_contacts>
        </collision>
        <visual name='GripL4_visual'>
          <pose>0 0 0 0 -0 0</pose>
          <geometry>
            <mesh>
              <scale>1 1 1</scale>
              <uri>/home/johne/catkin_ws/src/davinci_final/meshes/GripL4.STL</uri>
            </mesh>
          </geometry>
        </visual>
        <visual name='GripL4_fixed_joint_lump__Gripper2_visual_1'>
          <pose>-0.015 -0.31338 -0.006018 0 -0 0.35499</pose>
          <geometry>
            <mesh>
              <scale>1 1 1</scale>
              <uri>/home/johne/catkin_ws/src/davinci_final/meshes/Gripper2.STL</uri>
            </mesh>
          </geometry>
        </visual>
        <velocity_decay/>
        <gravity>0</gravity>
        <velocity_decay/>
        <self_collide>0</self_collide>
        <enable_wind>0</enable_wind>
        <kinematic>0</kinematic>
      </link>
      <joint name='GripperJ1' type='revolute'>
        <pose relative_to='GripL4'>0.015 -0.31338 0 0 0 -0.17792</pose>
        <parent>GripL4</parent>
        <child>Gripper1</child>
        <axis>
          <xyz>0 0 1</xyz>
          <limit>
            <lower>-2.45</lower>
            <upper>2.45</upper>
            <effort>30</effort>
            <velocity>3.4</velocity>
          </limit>
          <dynamics>
            <spring_reference>0</spring_reference>
            <spring_stiffness>0</spring_stiffness>
          </dynamics>
        </axis>
      </joint>
      <link name='Gripper1'>
        <pose relative_to='GripperJ1'>0 0 0 0 -0 0</pose>
        <inertial>
          <pose>0 -0.016944 0.009 0 -0 0</pose>
          <mass>0.00228575</mass>
          <inertia>
            <ixx>4.41989e-07</ixx>
            <ixy>0</ixy>
            <ixz>0</ixz>
            <iyy>2.66774e-08</iyy>
            <iyz>0</iyz>
            <izz>4.67142e-07</izz>
          </inertia>
        </inertial>
        <collision name='Gripper1_collision'>
          <pose>0 -0.016944 0.009 0 -0 0</pose>
          <geometry>
            <mesh>
              <scale>1 1 1</scale>
              <uri>/home/johne/catkin_ws/src/davinci_final/meshes/Gripper1.STL</uri>
            </mesh>
          </geometry>
          <surface>
            <contact>
              <ode/>
            </contact>
            <friction>
              <ode/>
              <torsional>
                <ode/>
              </torsional>
            </friction>
            <bounce/>
          </surface>
          <max_contacts>10</max_contacts>
        </collision>
        <visual name='Gripper1_visual'>
          <pose>0 0 0 0 -0 0</pose>
          <geometry>
            <mesh>
              <scale>1 1 1</scale>
              <uri>/home/johne/catkin_ws/src/davinci_final/meshes/Gripper1.STL</uri>
            </mesh>
          </geometry>
        </visual>
        <gravity>0</gravity>
        <velocity_decay/>
        <self_collide>0</self_collide>
        <enable_wind>0</enable_wind>
        <kinematic>0</kinematic>
      </link>
      <static>0</static>
      <plugin name='gazebo_ros_control' filename='libgazebo_ros_control.so'>
        <robotNamespace>/davinci_final/</robotNamespace>
        <robotSimType>gazebo_ros_control/DefaultRobotHWSim</robotSimType>
        <legacyModeNS>1</legacyModeNS>
      </plugin>
      <pose>0 0 0 0 -0 0</pose>
    </model>
    <state world_name='default'>
      <sim_time>19 985000000</sim_time>
      <real_time>26 828098416</real_time>
      <wall_time>1620528575 973725922</wall_time>
      <iterations>19985</iterations>
      <model name='davinci_final'>
        <pose>0.071599 -0.112296 0.325112 -0.002771 -0.00132 0.108373</pose>
        <scale>1 1 1</scale>
        <link name='Base'>
          <pose>0.071599 -0.112296 0.325112 -0.002771 -0.00132 0.108373</pose>
          <velocity>-0.006209 -0.001346 -0.015161 -0.000257 -0.009957 0.000987</velocity>
          <acceleration>-0.263792 -0.402724 -6.37706 -1.16795 0.720254 -2.1917</acceleration>
          <wrench>-198.588 -303.179 -4800.79 0 -0 0</wrench>
        </link>
        <link name='CamL1'>
          <pose>1.25977 -0.251867 1.3857 1.85978 -0.125624 2.85481</pose>
          <velocity>-0.015431 0.001451 0.003349 0.00293 -0.006245 0.015496</velocity>
          <acceleration>-5.56744 5.23199 -1.36371 0.004546 -1.15873 -2.62822</acceleration>
          <wrench>-111.493 104.775 -27.3095 0 -0 0</wrench>
        </link>
        <link name='CamL2'>
          <pose>1.22848 -0.290116 1.23374 1.74889 0.785229 1.41059</pose>
          <velocity>-0.0166 0.002771 0.003945 0.003124 -0.005642 0.015887</velocity>
          <acceleration>-2.58814 4.91855 -1.05024 -1.67372 0.162018 -2.37649</acceleration>
          <wrench>-63.739 121.131 -25.8646 0 -0 0</wrench>
        </link>
        <link name='CamL3'>
          <pose>1.03313 -0.835917 0.972632 1.44204 -0.220427 -1.82929</pose>
          <velocity>-0.001991 -0.000398 -0.000109 0.003158 -0.005446 0.0159</velocity>
          <acceleration>1.44108 3.81714 -0.792904 -2.7418 -0.001448 2.41083</acceleration>
          <wrench>2.40379 6.36714 -1.32259 0 -0 0</wrench>
        </link>
        <link name='CamL4'>
          <pose>0.955361 -0.949413 1.0078 1.35269 -0.132679 -1.33123</pose>
          <velocity>0.001671 -0.002778 -0.001648 0.002917 -0.005862 0.014801</velocity>
          <acceleration>2.60979 3.84273 -0.847072 3.06704 -0.499862 2.55814</acceleration>
          <wrench>0.486832 0.716826 -0.158014 0 -0 0</wrench>
        </link>
        <link name='GripL1'>
          <pose>0.756226 -0.543941 1.67885 2.0203 -0.114715 -2.8018</pose>
          <velocity>-0.017986 0.000281 -0.001948 -0.000261 -0.009971 0.000982</velocity>
          <acceleration>-6.26949 6.37575 -1.94025 -1.26934 -1.56756 -1.69727</acceleration>
          <wrench>-128.639 130.819 -39.8105 0 -0 0</wrench>
        </link>
        <link name='GripL2'>
          <pose>0.762391 -0.60142 1.56303 1.68886 0.238327 1.93858</pose>
          <velocity>-0.016274 0.000226 -0.002405 -0.000644 -0.010089 0.001013</velocity>
          <acceleration>-6.16698 6.12567 -1.00355 -1.62101 -1.33755 -0.642628</acceleration>
          <wrench>-108.54 107.813 -17.6627 0 -0 0</wrench>
        </link>
        <link name='GripL3'>
          <pose>0.819443 -0.888001 1.2009 1.44907 -0.340284 -1.1902</pose>
          <velocity>-0.009846 -7.9e-05 -0.001264 -0.000658 -0.010088 0.000993</velocity>
          <acceleration>-5.66839 5.585 -0.31816 -2.63657 -0.620593 -0.122382</acceleration>
          <wrench>-9.45511 9.31601 -0.530703 0 -0 0</wrench>
        </link>
        <link name='GripL4'>
          <pose>0.822813 -1.02084 1.251 1.42771 0.332139 1.18409</pose>
          <velocity>-0.009882 -0.000344 -0.001093 -0.000624 -0.008413 0.024975</velocity>
          <acceleration>-8.78143 5.09611 0.348857 -1.84644 0.450477 0.535544</acceleration>
          <wrench>-1.7576 1.01999 0.069824 0 -0 0</wrench>
        </link>
        <link name='Gripper1'>
          <pose>0.831405 -1.11823 0.952886 1.41583 0.508273 1.15515</pose>
          <velocity>-0.006775 -0.000249 -0.001305 -0.004539 -0.018185 0.02161</velocity>
          <acceleration>-2.9069 1.49593 1.94183 -0.988643 -0.922243 -1.95774</acceleration>
          <wrench>-0.006644 0.003419 0.004439 0 -0 0</wrench>
        </link>
      </model>
      <model name='ground_plane'>
        <pose>0 0 0 0 -0 0</pose>
        <scale>1 1 1</scale>
        <link name='link'>
          <pose>0 0 0 0 -0 0</pose>
          <velocity>0 0 0 0 -0 0</velocity>
          <acceleration>0 0 0 0 -0 0</acceleration>
          <wrench>0 0 0 0 -0 0</wrench>
        </link>
      </model>
      <model name='unit_sphere'>
        <pose>0.979215 -1.08796 1.0612 0 -0 0</pose>
        <scale>1 1 1</scale>
        <link name='link'>
          <pose>0.979215 -1.08796 1.0612 0 -0 0</pose>
          <velocity>0 0 0 0 -0 0</velocity>
          <acceleration>0 0 0 0 -0 0</acceleration>
          <wrench>0 0 0 0 -0 0</wrench>
        </link>
      </model>
      <light name='sun'>
        <pose>0 0 10 0 -0 0</pose>
      </light>
    </state>
    <model name='unit_sphere'>
      <link name='link'>
        <inertial>
          <mass>1</mass>
          <inertia>
            <ixx>0.1</ixx>
            <ixy>0</ixy>
            <ixz>0</ixz>
            <iyy>0.1</iyy>
            <iyz>0</iyz>
            <izz>0.1</izz>
          </inertia>
          <pose>0 0 0 0 -0 0</pose>
        </inertial>
        <self_collide>0</self_collide>
        <enable_wind>0</enable_wind>
        <kinematic>0</kinematic>
        <pose>0 0 0 0 -0 0</pose>
        <gravity>0</gravity>
        <visual name='visual'>
          <geometry>
            <sphere>
              <radius>0.0981048</radius>
            </sphere>
          </geometry>
          <material>
            <script>
              <name>Gazebo/Grey</name>
              <uri>file://media/materials/scripts/gazebo.material</uri>
            </script>
            <shader type='pixel'>
              <normal_map>__default__</normal_map>
            </shader>
          </material>
          <pose>0 0 0 0 -0 0</pose>
          <transparency>0</transparency>
          <cast_shadows>1</cast_shadows>
        </visual>
        <collision name='collision'>
          <laser_retro>0</laser_retro>
          <max_contacts>10</max_contacts>
          <pose>0 0 0 0 -0 0</pose>
          <geometry>
            <sphere>
              <radius>0.098105</radius>
            </sphere>
          </geometry>
          <surface>
            <friction>
              <ode>
                <mu>1</mu>
                <mu2>1</mu2>
                <fdir1>0 0 0</fdir1>
                <slip1>0</slip1>
                <slip2>0</slip2>
              </ode>
              <torsional>
                <coefficient>1</coefficient>
                <patch_radius>0</patch_radius>
                <surface_radius>0</surface_radius>
                <use_patch_radius>1</use_patch_radius>
                <ode>
                  <slip>0</slip>
                </ode>
              </torsional>
            </friction>
            <bounce>
              <restitution_coefficient>0</restitution_coefficient>
              <threshold>1e+06</threshold>
            </bounce>
            <contact>
              <collide_without_contact>0</collide_without_contact>
              <collide_without_contact_bitmask>1</collide_without_contact_bitmask>
              <collide_bitmask>1</collide_bitmask>
              <ode>
                <soft_cfm>0</soft_cfm>
                <soft_erp>0.2</soft_erp>
                <kp>1e+13</kp>
                <kd>1</kd>
                <max_vel>0.01</max_vel>
                <min_depth>0</min_depth>
              </ode>
              <bullet>
                <split_impulse>1</split_impulse>
                <split_impulse_penetration_threshold>-0.01</split_impulse_penetration_threshold>
                <soft_cfm>0</soft_cfm>
                <soft_erp>0.2</soft_erp>
                <kp>1e+13</kp>
                <kd>1</kd>
              </bullet>
            </contact>
          </surface>
        </collision>
      </link>
      <static>0</static>
      <allow_auto_disable>1</allow_auto_disable>
      <pose>-0.489885 -1.24252 0.098105 0 -0 0</pose>
    </model>
    <gui fullscreen='0'>
      <camera name='user_camera'>
        <pose>1.48135 -4.50761 2.45216 0 0.530699 1.68476</pose>
        <view_controller>orbit</view_controller>
        <projection_type>perspective</projection_type>
      </camera>
    </gui>
  </world>
</sdf>
